<?xml version="1.0" encoding="utf-8"?>
<!-- This URDF was automatically created by SolidWorks to URDF Exporter! Originally created by Stephen Brawner (brawner@gmail.com) 
     Commit Version: 1.5.1-0-g916b5db  Build Version: 1.5.7152.31018
     For more information, please see http://wiki.ros.org/sw_urdf_exporter -->
<robot
  name="wheel_chair">
  <link
    name="base_link">
    <inertial>
      <origin
        xyz="0.367710115990865 0.00427594055759772 0.222806503300556"
        rpy="0 0 0" />
      <mass
        value="104.238834662291" />
      <inertia
        ixx="4.71175664250457"
        ixy="0.0385230868676068"
        ixz="1.0740814957226"
        iyy="7.70372211875449"
        iyz="0.0449177005185298"
        izz="4.26521836376027" />
    </inertial>
    <visual>
      <origin
        xyz="0 0 0"
        rpy="0 0 0" />
      <geometry>
        <mesh
          filename="package://wheel_chair/meshes/base_link.STL" />
      </geometry>
      <material
        name="">
        <color
          rgba="0.2 0.2 0.2 1" />
      </material>
    </visual>
    <collision>
      <origin
        xyz="0 0 0"
        rpy="0 0 0" />
      <geometry>
        <mesh
          filename="package://wheel_chair/meshes/base_link.STL" />
      </geometry>
    </collision>
  </link>
  <link
    name="left_big_wheel">
    <inertial>
      <origin
        xyz="8.32667268468867E-17 -0.0275 9.43689570931383E-16"
        rpy="0 0 0" />
      <mass
        value="3.19005851775017" />
      <inertia
        ixx="0.0222055020892376"
        ixy="2.73068863816006E-19"
        ixz="-2.79570503430672E-17"
        iyy="0.0429444812918596"
        iyz="-3.90098376880016E-20"
        izz="0.0222055020892377" />
    </inertial>
    <visual>
      <origin
        xyz="0 0 0"
        rpy="0 0 0" />
      <geometry>
        <mesh
          filename="package://wheel_chair/meshes/left_big_wheel.STL" />
      </geometry>
      <material
        name="">
        <color
          rgba="0.298039215686275 0.298039215686275 0.298039215686275 1" />
      </material>
    </visual>
    <collision>
      <origin
        xyz="0 0 0"
        rpy="0 0 0" />
      <geometry>
        <mesh
          filename="package://wheel_chair/meshes/left_big_wheel.STL" />
      </geometry>
    </collision>
  </link>
  <joint
    name="left_big_wheel_joint"
    type="continuous">
    <origin
      xyz="0 0.315 0"
      rpy="0 0 0" />
    <parent
      link="base_link" />
    <child
      link="left_big_wheel" />
    <axis
      xyz="0 -1 0" />
    <limit
      effort="1"
      velocity="1" />
  </joint>
  <link
    name="right_big_wheel">
    <inertial>
      <origin
        xyz="1.60982338570648E-15 0.0275 1.11022302462516E-15"
        rpy="0 0 0" />
      <mass
        value="3.19005851775018" />
      <inertia
        ixx="0.0222055020892377"
        ixy="-5.02793463534266E-19"
        ixz="-1.06280135567754E-17"
        iyy="0.0429444812918596"
        iyz="1.34367218703133E-19"
        izz="0.0222055020892377" />
    </inertial>
    <visual>
      <origin
        xyz="0 0 0"
        rpy="0 0 0" />
      <geometry>
        <mesh
          filename="package://wheel_chair/meshes/right_big_wheel.STL" />
      </geometry>
      <material
        name="">
        <color
          rgba="0.298039215686275 0.298039215686275 0.298039215686275 1" />
      </material>
    </visual>
    <collision>
      <origin
        xyz="0 0 0"
        rpy="0 0 0" />
      <geometry>
        <mesh
          filename="package://wheel_chair/meshes/right_big_wheel.STL" />
      </geometry>
    </collision>
  </link>
  <joint
    name="right_big_wheel_joint"
    type="continuous">
    <origin
      xyz="0 -0.315 0"
      rpy="0 0 0" />
    <parent
      link="base_link" />
    <child
      link="right_big_wheel" />
    <axis
      xyz="0 -1 0" />
    <limit
      effort="1"
      velocity="1" />
  </joint>
  <link
    name="left_small_wheel">
    <inertial>
      <origin
        xyz="-7.21644966006352E-16 -0.0400000000000002 0"
        rpy="0 0 0" />
      <mass
        value="1.31881639542862" />
      <inertia
        ixx="0.00307756206748821"
        ixy="-4.86196911723968E-19"
        ixz="1.29760768970133E-20"
        iyy="0.00569232821091254"
        iyz="1.99882167723138E-20"
        izz="0.00307756206748821" />
    </inertial>
    <visual>
      <origin
        xyz="0 0 0"
        rpy="0 0 0" />
      <geometry>
        <mesh
          filename="package://wheel_chair/meshes/left_small_wheel.STL" />
      </geometry>
      <material
        name="">
        <color
          rgba="0.298039215686275 0.298039215686275 0.298039215686275 1" />
      </material>
    </visual>
    <collision>
      <origin
        xyz="0 0 0"
        rpy="0 0 0" />
      <geometry>
        <mesh
          filename="package://wheel_chair/meshes/left_small_wheel.STL" />
      </geometry>
    </collision>
  </link>
  <joint
    name="left_small_wheel_joint"
    type="revolute">
    <origin
      xyz="0.64005 0.2835 -0.065"
      rpy="0 0 -0.0013615" />
    <parent
      link="base_link" />
    <child
      link="left_small_wheel" />
    <axis
      xyz="-0.0019131 1 0" />
    <limit
      lower="0"
      upper="0"
      effort="0"
      velocity="0" />
  </joint>
  <link
    name="right_smaal_wheel">
    <inertial>
      <origin
        xyz="0.000198873647039965 0.0399995056128514 2.22044604925031E-15"
        rpy="0 0 0" />
      <mass
        value="1.31881639542862" />
      <inertia
        ixx="0.00307762670242769"
        ixy="1.30000412990577E-05"
        ixz="-3.05847536861125E-19"
        iyy="0.00569226357597306"
        iyz="8.08608700453136E-20"
        izz="0.00307756206748821" />
    </inertial>
    <visual>
      <origin
        xyz="0 0 0"
        rpy="0 0 0" />
      <geometry>
        <mesh
          filename="package://wheel_chair/meshes/right_smaal_wheel.STL" />
      </geometry>
      <material
        name="">
        <color
          rgba="0.298039215686275 0.298039215686275 0.298039215686275 1" />
      </material>
    </visual>
    <collision>
      <origin
        xyz="0 0 0"
        rpy="0 0 0" />
      <geometry>
        <mesh
          filename="package://wheel_chair/meshes/right_smaal_wheel.STL" />
      </geometry>
    </collision>
  </link>
  <joint
    name="right_small_wheel_joint"
    type="revolute">
    <origin
      xyz="0.6398 -0.2835 -0.065"
      rpy="0 0 0" />
    <parent
      link="base_link" />
    <child
      link="right_smaal_wheel" />
    <axis
      xyz="0.0043627 0.99999 0" />
    <limit
      lower="0"
      upper="0"
      effort="0"
      velocity="0" />
  </joint>
  <link
    name="rp_laser_back">
    <inertial>
      <origin
        xyz="-0.00393393719392465 1.45541326387055E-05 -0.00550433759472346"
        rpy="0 0 0" />
      <mass
        value="0.165382757413928" />
      <inertia
        ixx="7.88186497400901E-05"
        ixy="4.81327415297136E-08"
        ixz="-1.82339073198479E-06"
        iyy="7.51902892774038E-05"
        iyz="-2.9420939238945E-08"
        izz="0.000109993288450695" />
    </inertial>
    <visual>
      <origin
        xyz="0 0 0"
        rpy="0 0 0" />
      <geometry>
        <mesh
          filename="package://wheel_chair/meshes/rp_laser_back.STL" />
      </geometry>
      <material
        name="">
        <color
          rgba="0.752941176470588 0.752941176470588 0.752941176470588 0.4" />
      </material>
    </visual>
    <collision>
      <origin
        xyz="0 0 0"
        rpy="0 0 0" />
      <geometry>
        <mesh
          filename="package://wheel_chair/meshes/rp_laser_back.STL" />
      </geometry>
    </collision>
  </link>
  <joint
    name="rp_laser_back_joint"
    type="fixed">
    <origin
      xyz="-0.048279 0.305 0.26099"
      rpy="0 0 -0.4" />
    <parent
      link="base_link" />
    <child
      link="rp_laser_back" />
    <axis
      xyz="0 0 0" />
  </joint>
  <link
    name="rp_laser_front">
    <inertial>
      <origin
        xyz="0.00386881875434386 8.69539989361567E-05 -0.00554963797433417"
        rpy="0 0 0" />
      <mass
        value="0.165382751635991" />
      <inertia
        ixx="7.88601133328312E-05"
        ixy="1.44763696263324E-07"
        ixz="2.18328573965282E-06"
        iyy="7.51953617715746E-05"
        iyz="8.61570136662877E-08"
        izz="0.000109946753058707" />
    </inertial>
    <visual>
      <origin
        xyz="0 0 0"
        rpy="0 0 0" />
      <geometry>
        <mesh
          filename="package://wheel_chair/meshes/rp_laser_front.STL" />
      </geometry>
      <material
        name="">
        <color
          rgba="0.752941176470588 0.752941176470588 0.752941176470588 0.4" />
      </material>
    </visual>
    <collision>
      <origin
        xyz="0 0 0"
        rpy="0 0 0" />
      <geometry>
        <mesh
          filename="package://wheel_chair/meshes/rp_laser_front.STL" />
      </geometry>
    </collision>
  </link>
  <joint
    name="rp_laser_front_joint"
    type="fixed">
    <origin
      xyz="0.72155 0.0046595 -0.074152"
      rpy="0 0 -0.0013615" />
    <parent
      link="base_link" />
    <child
      link="rp_laser_front" />
    <axis
      xyz="0 0 0" />
  </joint>
  <link
    name="camera_link">
    <inertial>
      <origin
        xyz="-0.0128303971236894 0.00026345822416235 0.00120890752799729"
        rpy="0 0 0" />
      <mass
        value="0.0247927922484064" />
      <inertia
        ixx="3.56506588599453E-05"
        ixy="-1.15721449744488E-08"
        ixz="-1.82266916058428E-07"
        iyy="2.84011177762109E-06"
        iyz="2.78716575004723E-08"
        izz="3.35091990190486E-05" />
    </inertial>
    <visual>
      <origin
        xyz="0 0 0"
        rpy="0 0 0" />
      <geometry>
        <mesh
          filename="package://wheel_chair/meshes/camera.STL" />
      </geometry>
      <material
        name="">
        <color
          rgba="0.792156862745098 0.819607843137255 0.933333333333333 1" />
      </material>
    </visual>
    <collision>
      <origin
        xyz="0 0 0"
        rpy="0 0 0" />
      <geometry>
        <mesh
          filename="package://wheel_chair/meshes/camera.STL" />
      </geometry>
    </collision>
  </link>
  <joint
    name="camera_joint"
    type="fixed">
    <origin
      xyz="-0.066986 -0.0039691 1.5345"
      rpy="0 0 0" />
    <parent
      link="base_link" />
    <child
      link="camera_link" />
    <axis
      xyz="0 0 0" />
    <limit
      lower="0"
      upper="0"
      effort="0"
      velocity="0" />
  </joint>
  
  <joint name="camera_depth_joint" type="fixed">
    <origin xyz="0 0 0" rpy="0 0 0"/>
    <parent link="camera_link"/>
    <child link="camera_depth_frame" />
  </joint>
  <link name="camera_depth_frame"/>

  <joint name="camera_depth_optical_joint" type="fixed">
    <origin xyz="0 0 0" rpy="-1.57079632679 0 -1.57079632679" />
    <parent link="camera_depth_frame" />
    <child link="camera_depth_optical_frame" />
  </joint>
  <link name="camera_depth_optical_frame"/>

  <!-- camera left IR joints and links -->
  <joint name="camera_infra1_joint" type="fixed">
    <origin xyz="0 0 0" rpy="0 0 0" />
    <parent link="camera_link" />
    <child link="camera_infra1_frame" />
  </joint>
  <link name="camera_infra1_frame"/>

  <joint name="camera_infra1_optical_joint" type="fixed">
    <origin xyz="0 0 0" rpy="-1.57079632679 0 -1.57079632679" />
    <parent link="camera_infra1_frame" />
    <child link="camera_infra1_optical_frame" />
  </joint>
  <link name="camera_infra1_optical_frame"/>

  <!-- camera right IR joints and links -->
  <joint name="camera_infra2_joint" type="fixed">
    <origin xyz="0 -0.095 0" rpy="0 0 0" />
    <parent link="camera_link" />
    <child link="camera_infra2_frame" />
  </joint>
  <link name="camera_infra2_frame"/>

  <joint name="camera_infra2_optical_joint" type="fixed">
    <origin xyz="0 0 0" rpy="-1.57079632679 0 -1.57079632679" />
    <parent link="camera_infra2_frame" />
    <child link="camera_infra2_optical_frame" />
  </joint>
  <link name="camera_infra2_optical_frame"/>

  <!-- camera color joints and links -->
  <joint name="camera_color_joint" type="fixed">
    <origin xyz="0 -0.059 0" rpy="0 0 0" />
    <parent link="camera_link" />
    <child link="camera_color_frame" />
  </joint>
  <link name="camera_color_frame"/>

  <joint name="camera_color_optical_joint" type="fixed">
    <origin xyz="0 0 0" rpy="-1.57079632679 0 -1.57079632679" />
    <parent link="camera_color_frame" />
    <child link="camera_color_optical_frame" />
  </joint>
  <link name="camera_color_optical_frame"/>

  <link name="camera_accel_frame" />
  <link name="camera_accel_optical_frame" />
  <link name="camera_gyro_frame" />
  <link name="camera_gyro_optical_frame" />
  <link name="camera_imu_optical_frame" />

<!-- IMU -->
  <!-- see datasheet Revision 009, page 114 -->
  <!--xacro:property name="d455_imu_px" value="-0.01602"/>
  <xacro:property name="d455_imu_py" value="-0.03022"/>
  <xacro:property name="d455_imu_pz" value="+0.0074"/-->

  <joint name="camera_accel_joint" type="fixed">
    <origin xyz = "-0.01602 -0.03022 +0.0074" rpy = "0 0 0" />
    <parent link="camera_link" />
    <child link="camera_accel_frame" />
  </joint>

  <joint name="camera_accel_optical_joint" type="fixed">
    <origin xyz = "0 0 0" rpy = "-1.57 0 -1.57" />
    <parent link="camera_accel_frame" />
    <child link="camera_accel_optical_frame" />
  </joint>

  <joint name="camera_gyro_joint" type="fixed">
    <origin xyz = "-0.01602 -0.03022 +0.0074" rpy = "0 0 0" />
    <parent link="camera_link" />
    <child link="camera_gyro_frame" />
  </joint>

  <joint name="camera_gyro_optical_joint" type="fixed">
    <origin xyz = "0 0 0" rpy = "-1.57 0 -1.57" />
    <parent link="camera_gyro_frame" />
    <child link="camera_gyro_optical_frame" />
  </joint>

  <joint name="camera_imu_optical_joint" type="fixed">
    <origin xyz = "0 0 0" rpy = "0 0 0" />
    <parent link="camera_gyro_optical_frame" />
    <child link="camera_imu_optical_frame" />
  </joint>

</robot>